2019-01-12 10:39:52,178 ERROR    Exception occured in gene 0
Traceback (most recent call last):
  File "/Users/jiayu/PycharmProjects/CBM_RA/projects2018_immunopepper/immunopepper/main_immuno.py", line 194, in main
    assert 5 < 0
AssertionError
2019-01-12 10:40:23,993 ERROR    Exception occured in gene 0
Traceback (most recent call last):
  File "/Users/jiayu/PycharmProjects/CBM_RA/projects2018_immunopepper/immunopepper/main_immuno.py", line 194, in main
    assert 5 < 0
AssertionError
